<?xml version="1.0" ?>
<!-- =================================================================================== -->
<!-- |    This document was autogenerated by xacro from spider2.xacro                  | -->
<!-- |    EDITING THIS FILE BY HAND IS NOT RECOMMENDED                                 | -->
<!-- =================================================================================== -->
<robot name="spider" xmlns:xacro="http://www.ros.org/wiki/xacro">
  <link name="a+'_1'">
    <visual>
      <geometry>
        <cylinder length="0.4" radius="0.1"/>
      </geometry>
      <origin rpy="0 1.57285 0" xyz="0.2 0 0"/>
      <material name="cyan">
        <color rgba="0 1 1 1"/>
      </material>
    </visual>
  </link>
  <link name="a+'_2'">
    <visual>
      <geometry>
        <cylinder length="0.5" radius="0.1"/>
      </geometry>
      <origin rpy="0 1.57285 0" xyz="0.25 0 0"/>
      <material name="yellow">
        <color rgba="1 1 0 1"/>
      </material>
    </visual>
    <collision>
      <geometry>
        <cylinder length="0.5" radius="0.1"/>
      </geometry>
      <origin rpy="0 1.57285 0" xyz="0.25 0 0"/>
      <material name="yellow">
        <color rgba="1 1 0 1"/>
      </material>
    </collision>
  </link>
  <link name="a+'_3'">
    <visual>
      <geometry>
        <cylinder length="0.6" radius="0.1"/>
      </geometry>
      <origin rpy="0 1.57285 0" xyz="0.3 0 0"/>
      <material name="red">
        <color rgba="1 0 0 1"/>
      </material>
    </visual>
    <collision>
      <geometry>
        <cylinder length="0.6" radius="0.1"/>
      </geometry>
      <origin rpy="0 1.57285 0" xyz="0.3 0 0"/>
      <material name="red">
        <color rgba="1 0 0 1"/>
      </material>
    </collision>
  </link>
  <link name="a+'_4'">
    <visual>
      <geometry>
        <sphere radius="0.1"/>
      </geometry>
      <origin rpy="0 1.57285 0" xyz="0.3 0 0"/>
      <material name="red">
        <color rgba="1 0 0 1"/>
      </material>
    </visual>
    <collision>
      <geometry>
        <sphere radius="0.1"/>
      </geometry>
      <origin rpy="0 1.57285 0" xyz="0.3 0 0"/>
      <material name="red">
        <color rgba="1 0 0 1"/>
      </material>
    </collision>
  </link>
  <joint name="a+'_1_2'" type="revolute">
    <parent link="a+'_1'"/>
    <child link="a+'_2'"/>
    <origin rpy="0 0 0" xyz="0.4 0 0"/>
    <axis xyz="0 1 0"/>
    <limit effort="300" lower="-1.57" upper="1.57" velocity="0.1"/>
  </joint>
  <joint name="a+'_2_3'" type="revolute">
    <parent link="a+'_2'"/>
    <child link="a+'_3'"/>
    <origin rpy="0 0 0" xyz="0.5 0 0"/>
    <axis xyz="0 1 0"/>
    <limit effort="300" lower="-1.57" upper="1.57" velocity="0.1"/>
  </joint>
  <joint name="a+'_3_4'" type="fixed">
    <parent link="a+'_3'"/>
    <child link="a+'_4'"/>
    <origin xyz="0.3 0 0"/>
  </joint>
  <link name="b+'_1'">
    <visual>
      <geometry>
        <cylinder length="0.4" radius="0.1"/>
      </geometry>
      <origin rpy="0 1.57285 0" xyz="0.2 0 0"/>
      <material name="cyan">
        <color rgba="0 1 1 1"/>
      </material>
    </visual>
  </link>
  <link name="b+'_2'">
    <visual>
      <geometry>
        <cylinder length="0.5" radius="0.1"/>
      </geometry>
      <origin rpy="0 1.57285 0" xyz="0.25 0 0"/>
      <material name="yellow">
        <color rgba="1 1 0 1"/>
      </material>
    </visual>
    <collision>
      <geometry>
        <cylinder length="0.5" radius="0.1"/>
      </geometry>
      <origin rpy="0 1.57285 0" xyz="0.25 0 0"/>
      <material name="yellow">
        <color rgba="1 1 0 1"/>
      </material>
    </collision>
  </link>
  <link name="b+'_3'">
    <visual>
      <geometry>
        <cylinder length="0.6" radius="0.1"/>
      </geometry>
      <origin rpy="0 1.57285 0" xyz="0.3 0 0"/>
      <material name="red">
        <color rgba="1 0 0 1"/>
      </material>
    </visual>
    <collision>
      <geometry>
        <cylinder length="0.6" radius="0.1"/>
      </geometry>
      <origin rpy="0 1.57285 0" xyz="0.3 0 0"/>
      <material name="red">
        <color rgba="1 0 0 1"/>
      </material>
    </collision>
  </link>
  <link name="b+'_4'">
    <visual>
      <geometry>
        <sphere radius="0.1"/>
      </geometry>
      <origin rpy="0 1.57285 0" xyz="0.3 0 0"/>
      <material name="red">
        <color rgba="1 0 0 1"/>
      </material>
    </visual>
    <collision>
      <geometry>
        <sphere radius="0.1"/>
      </geometry>
      <origin rpy="0 1.57285 0" xyz="0.3 0 0"/>
      <material name="red">
        <color rgba="1 0 0 1"/>
      </material>
    </collision>
  </link>
  <joint name="b+'_1_2'" type="revolute">
    <parent link="b+'_1'"/>
    <child link="b+'_2'"/>
    <origin rpy="0 0 0" xyz="0.4 0 0"/>
    <axis xyz="0 1 0"/>
    <limit effort="300" lower="-1.57" upper="1.57" velocity="0.1"/>
  </joint>
  <joint name="b+'_2_3'" type="revolute">
    <parent link="b+'_2'"/>
    <child link="b+'_3'"/>
    <origin rpy="0 0 0" xyz="0.5 0 0"/>
    <axis xyz="0 1 0"/>
    <limit effort="300" lower="-1.57" upper="1.57" velocity="0.1"/>
  </joint>
  <joint name="b+'_3_4'" type="fixed">
    <parent link="b+'_3'"/>
    <child link="b+'_4'"/>
    <origin xyz="0.3 0 0"/>
  </joint>
  <link name="c+'_1'">
    <visual>
      <geometry>
        <cylinder length="0.4" radius="0.1"/>
      </geometry>
      <origin rpy="0 1.57285 0" xyz="0.2 0 0"/>
      <material name="cyan">
        <color rgba="0 1 1 1"/>
      </material>
    </visual>
  </link>
  <link name="c+'_2'">
    <visual>
      <geometry>
        <cylinder length="0.5" radius="0.1"/>
      </geometry>
      <origin rpy="0 1.57285 0" xyz="0.25 0 0"/>
      <material name="yellow">
        <color rgba="1 1 0 1"/>
      </material>
    </visual>
    <collision>
      <geometry>
        <cylinder length="0.5" radius="0.1"/>
      </geometry>
      <origin rpy="0 1.57285 0" xyz="0.25 0 0"/>
      <material name="yellow">
        <color rgba="1 1 0 1"/>
      </material>
    </collision>
  </link>
  <link name="c+'_3'">
    <visual>
      <geometry>
        <cylinder length="0.6" radius="0.1"/>
      </geometry>
      <origin rpy="0 1.57285 0" xyz="0.3 0 0"/>
      <material name="red">
        <color rgba="1 0 0 1"/>
      </material>
    </visual>
    <collision>
      <geometry>
        <cylinder length="0.6" radius="0.1"/>
      </geometry>
      <origin rpy="0 1.57285 0" xyz="0.3 0 0"/>
      <material name="red">
        <color rgba="1 0 0 1"/>
      </material>
    </collision>
  </link>
  <link name="c+'_4'">
    <visual>
      <geometry>
        <sphere radius="0.1"/>
      </geometry>
      <origin rpy="0 1.57285 0" xyz="0.3 0 0"/>
      <material name="red">
        <color rgba="1 0 0 1"/>
      </material>
    </visual>
    <collision>
      <geometry>
        <sphere radius="0.1"/>
      </geometry>
      <origin rpy="0 1.57285 0" xyz="0.3 0 0"/>
      <material name="red">
        <color rgba="1 0 0 1"/>
      </material>
    </collision>
  </link>
  <joint name="c+'_1_2'" type="revolute">
    <parent link="c+'_1'"/>
    <child link="c+'_2'"/>
    <origin rpy="0 0 0" xyz="0.4 0 0"/>
    <axis xyz="0 1 0"/>
    <limit effort="300" lower="-1.57" upper="1.57" velocity="0.1"/>
  </joint>
  <joint name="c+'_2_3'" type="revolute">
    <parent link="c+'_2'"/>
    <child link="c+'_3'"/>
    <origin rpy="0 0 0" xyz="0.5 0 0"/>
    <axis xyz="0 1 0"/>
    <limit effort="300" lower="-1.57" upper="1.57" velocity="0.1"/>
  </joint>
  <joint name="c+'_3_4'" type="fixed">
    <parent link="c+'_3'"/>
    <child link="c+'_4'"/>
    <origin xyz="0.3 0 0"/>
  </joint>
  <link name="d+'_1'">
    <visual>
      <geometry>
        <cylinder length="0.4" radius="0.1"/>
      </geometry>
      <origin rpy="0 1.57285 0" xyz="0.2 0 0"/>
      <material name="cyan">
        <color rgba="0 1 1 1"/>
      </material>
    </visual>
  </link>
  <link name="d+'_2'">
    <visual>
      <geometry>
        <cylinder length="0.5" radius="0.1"/>
      </geometry>
      <origin rpy="0 1.57285 0" xyz="0.25 0 0"/>
      <material name="yellow">
        <color rgba="1 1 0 1"/>
      </material>
    </visual>
    <collision>
      <geometry>
        <cylinder length="0.5" radius="0.1"/>
      </geometry>
      <origin rpy="0 1.57285 0" xyz="0.25 0 0"/>
      <material name="yellow">
        <color rgba="1 1 0 1"/>
      </material>
    </collision>
  </link>
  <link name="d+'_3'">
    <visual>
      <geometry>
        <cylinder length="0.6" radius="0.1"/>
      </geometry>
      <origin rpy="0 1.57285 0" xyz="0.3 0 0"/>
      <material name="red">
        <color rgba="1 0 0 1"/>
      </material>
    </visual>
    <collision>
      <geometry>
        <cylinder length="0.6" radius="0.1"/>
      </geometry>
      <origin rpy="0 1.57285 0" xyz="0.3 0 0"/>
      <material name="red">
        <color rgba="1 0 0 1"/>
      </material>
    </collision>
  </link>
  <link name="d+'_4'">
    <visual>
      <geometry>
        <sphere radius="0.1"/>
      </geometry>
      <origin rpy="0 1.57285 0" xyz="0.3 0 0"/>
      <material name="red">
        <color rgba="1 0 0 1"/>
      </material>
    </visual>
    <collision>
      <geometry>
        <sphere radius="0.1"/>
      </geometry>
      <origin rpy="0 1.57285 0" xyz="0.3 0 0"/>
      <material name="red">
        <color rgba="1 0 0 1"/>
      </material>
    </collision>
  </link>
  <joint name="d+'_1_2'" type="revolute">
    <parent link="d+'_1'"/>
    <child link="d+'_2'"/>
    <origin rpy="0 0 0" xyz="0.4 0 0"/>
    <axis xyz="0 1 0"/>
    <limit effort="300" lower="-1.57" upper="1.57" velocity="0.1"/>
  </joint>
  <joint name="d+'_2_3'" type="revolute">
    <parent link="d+'_2'"/>
    <child link="d+'_3'"/>
    <origin rpy="0 0 0" xyz="0.5 0 0"/>
    <axis xyz="0 1 0"/>
    <limit effort="300" lower="-1.57" upper="1.57" velocity="0.1"/>
  </joint>
  <joint name="d+'_3_4'" type="fixed">
    <parent link="d+'_3'"/>
    <child link="d+'_4'"/>
    <origin xyz="0.3 0 0"/>
  </joint>
  <link name="base_link">
    <visual>
      <geometry>
        <box size="1 1 0.25"/>
      </geometry>
      <origin rpy="0 0 0" xyz="0 0 0"/>
      <material name="cyan">
        <color rgba="0 1 1 1"/>
      </material>
    </visual>
  </link>
  <link name="base_link2">
    <visual>
      <geometry>
        <box size="1 1 0.1"/>
      </geometry>
      <origin rpy="0 0 0" xyz="0 0 0"/>
      <material name="cyan">
        <color rgba="1 0 0 1"/>
      </material>
    </visual>
    <collision>
      <geometry>
        <box size="1 1 0.1"/>
      </geometry>
      <origin rpy="0 0 0" xyz="0 0 0"/>
      <material name="cyan">
        <color rgba="1 0 0 1"/>
      </material>
    </collision>
  </link>
  <joint name="base" type="fixed">
    <parent link="base_link"/>
    <child link="base_link2"/>
    <origin xyz="0 0 -0.075"/>
  </joint>
  <joint name="joint_0_a" type="revolute">
    <parent link="base_link"/>
    <child link="a+'_1'"/>
    <origin rpy="0 0 0.786425" xyz="0.5 0.5 0"/>
    <axis xyz="0 0 1"/>
    <limit effort="300" lower="-1.57" upper="1.57" velocity="0.1"/>
  </joint>
  <joint name="joint_0_b" type="revolute">
    <parent link="base_link"/>
    <child link="b+'_1'"/>
    <origin rpy="0 0 2.359275" xyz="-0.5 0.5 0"/>
    <axis xyz="0 0 1"/>
    <limit effort="300" lower="-1.57" upper="1.57" velocity="0.1"/>
  </joint>
  <joint name="joint_0_c" type="revolute">
    <parent link="base_link"/>
    <child link="c+'_1'"/>
    <origin rpy="0 0 3.932125" xyz="-0.5 -0.5 0"/>
    <axis xyz="0 0 1"/>
    <limit effort="300" lower="-1.57" upper="1.57" velocity="0.1"/>
  </joint>
  <joint name="joint_0_d" type="revolute">
    <parent link="base_link"/>
    <child link="d+'_1'"/>
    <origin rpy="0 0 5.504975" xyz="0.5 -0.5 0"/>
    <axis xyz="0 0 1"/>
    <limit effort="300" lower="-1.57" upper="1.57" velocity="0.1"/>
  </joint>
</robot>

