<?xml version="1.0" ?>
<!-- =================================================================================== -->
<!-- |    This document was autogenerated by xacro from spider3.xacro                  | -->
<!-- |    EDITING THIS FILE BY HAND IS NOT RECOMMENDED                                 | -->
<!-- =================================================================================== -->
<robot name="spider" xmlns:xacro="http://www.ros.org/wiki/xacro">
  <link name="env+a+'_1'">
    <visual>
      <geometry>
        <cylinder length="0.4" radius="0.1"/>
      </geometry>
      <origin rpy="0 1.57285 0" xyz="0.2 0 0"/>
      <material name="cyan">
        <color rgba="0 1 1 1"/>
      </material>
    </visual>
  </link>
  <link name="env+a+'_2'">
    <visual>
      <geometry>
        <cylinder length="0.5" radius="0.1"/>
      </geometry>
      <origin rpy="0 1.57285 0" xyz="0.25 0 0"/>
      <material name="yellow">
        <color rgba="1 1 0 1"/>
      </material>
    </visual>
    <collision>
      <geometry>
        <cylinder length="0.5" radius="0.1"/>
      </geometry>
      <origin rpy="0 1.57285 0" xyz="0.25 0 0"/>
      <material name="yellow">
        <color rgba="1 1 0 1"/>
      </material>
    </collision>
  </link>
  <link name="env+a+'_3'">
    <visual>
      <geometry>
        <cylinder length="0.6" radius="0.1"/>
      </geometry>
      <origin rpy="0 1.57285 0" xyz="0.3 0 0"/>
      <material name="red">
        <color rgba="1 0 0 1"/>
      </material>
    </visual>
    <collision>
      <geometry>
        <cylinder length="0.6" radius="0.1"/>
      </geometry>
      <origin rpy="0 1.57285 0" xyz="0.3 0 0"/>
      <material name="red">
        <color rgba="1 0 0 1"/>
      </material>
    </collision>
  </link>
  <link name="env+a+'_4'">
    <visual>
      <geometry>
        <sphere radius="0.1"/>
      </geometry>
      <origin rpy="0 1.57285 0" xyz="0.3 0 0"/>
      <material name="red">
        <color rgba="1 0 0 1"/>
      </material>
    </visual>
    <collision>
      <geometry>
        <sphere radius="0.1"/>
      </geometry>
      <origin rpy="0 1.57285 0" xyz="0.3 0 0"/>
      <material name="red">
        <color rgba="1 0 0 1"/>
      </material>
    </collision>
  </link>
  <joint name="env+a+'_1_2'" type="revolute">
    <parent link="env+a+'_1'"/>
    <child link="env+a+'_2'"/>
    <origin rpy="0 0 0" xyz="0.4 0 0"/>
    <axis xyz="0 1 0"/>
    <limit effort="300" lower="-1.57" upper="1.57" velocity="0.1"/>
  </joint>
  <joint name="env+a+'_2_3'" type="revolute">
    <parent link="env+a+'_2'"/>
    <child link="env+a+'_3'"/>
    <origin rpy="0 0 0" xyz="0.5 0 0"/>
    <axis xyz="0 1 0"/>
    <limit effort="300" lower="-1.57" upper="1.57" velocity="0.1"/>
  </joint>
  <joint name="env+a+'_3_4'" type="fixed">
    <parent link="env+a+'_3'"/>
    <child link="env+a+'_4'"/>
    <origin xyz="0.3 0 0"/>
  </joint>
  <link name="env+b+'_1'">
    <visual>
      <geometry>
        <cylinder length="0.4" radius="0.1"/>
      </geometry>
      <origin rpy="0 1.57285 0" xyz="0.2 0 0"/>
      <material name="cyan">
        <color rgba="0 1 1 1"/>
      </material>
    </visual>
  </link>
  <link name="env+b+'_2'">
    <visual>
      <geometry>
        <cylinder length="0.5" radius="0.1"/>
      </geometry>
      <origin rpy="0 1.57285 0" xyz="0.25 0 0"/>
      <material name="yellow">
        <color rgba="1 1 0 1"/>
      </material>
    </visual>
    <collision>
      <geometry>
        <cylinder length="0.5" radius="0.1"/>
      </geometry>
      <origin rpy="0 1.57285 0" xyz="0.25 0 0"/>
      <material name="yellow">
        <color rgba="1 1 0 1"/>
      </material>
    </collision>
  </link>
  <link name="env+b+'_3'">
    <visual>
      <geometry>
        <cylinder length="0.6" radius="0.1"/>
      </geometry>
      <origin rpy="0 1.57285 0" xyz="0.3 0 0"/>
      <material name="red">
        <color rgba="1 0 0 1"/>
      </material>
    </visual>
    <collision>
      <geometry>
        <cylinder length="0.6" radius="0.1"/>
      </geometry>
      <origin rpy="0 1.57285 0" xyz="0.3 0 0"/>
      <material name="red">
        <color rgba="1 0 0 1"/>
      </material>
    </collision>
  </link>
  <link name="env+b+'_4'">
    <visual>
      <geometry>
        <sphere radius="0.1"/>
      </geometry>
      <origin rpy="0 1.57285 0" xyz="0.3 0 0"/>
      <material name="red">
        <color rgba="1 0 0 1"/>
      </material>
    </visual>
    <collision>
      <geometry>
        <sphere radius="0.1"/>
      </geometry>
      <origin rpy="0 1.57285 0" xyz="0.3 0 0"/>
      <material name="red">
        <color rgba="1 0 0 1"/>
      </material>
    </collision>
  </link>
  <joint name="env+b+'_1_2'" type="revolute">
    <parent link="env+b+'_1'"/>
    <child link="env+b+'_2'"/>
    <origin rpy="0 0 0" xyz="0.4 0 0"/>
    <axis xyz="0 1 0"/>
    <limit effort="300" lower="-1.57" upper="1.57" velocity="0.1"/>
  </joint>
  <joint name="env+b+'_2_3'" type="revolute">
    <parent link="env+b+'_2'"/>
    <child link="env+b+'_3'"/>
    <origin rpy="0 0 0" xyz="0.5 0 0"/>
    <axis xyz="0 1 0"/>
    <limit effort="300" lower="-1.57" upper="1.57" velocity="0.1"/>
  </joint>
  <joint name="env+b+'_3_4'" type="fixed">
    <parent link="env+b+'_3'"/>
    <child link="env+b+'_4'"/>
    <origin xyz="0.3 0 0"/>
  </joint>
  <link name="env+c+'_1'">
    <visual>
      <geometry>
        <cylinder length="0.4" radius="0.1"/>
      </geometry>
      <origin rpy="0 1.57285 0" xyz="0.2 0 0"/>
      <material name="cyan">
        <color rgba="0 1 1 1"/>
      </material>
    </visual>
  </link>
  <link name="env+c+'_2'">
    <visual>
      <geometry>
        <cylinder length="0.5" radius="0.1"/>
      </geometry>
      <origin rpy="0 1.57285 0" xyz="0.25 0 0"/>
      <material name="yellow">
        <color rgba="1 1 0 1"/>
      </material>
    </visual>
    <collision>
      <geometry>
        <cylinder length="0.5" radius="0.1"/>
      </geometry>
      <origin rpy="0 1.57285 0" xyz="0.25 0 0"/>
      <material name="yellow">
        <color rgba="1 1 0 1"/>
      </material>
    </collision>
  </link>
  <link name="env+c+'_3'">
    <visual>
      <geometry>
        <cylinder length="0.6" radius="0.1"/>
      </geometry>
      <origin rpy="0 1.57285 0" xyz="0.3 0 0"/>
      <material name="red">
        <color rgba="1 0 0 1"/>
      </material>
    </visual>
    <collision>
      <geometry>
        <cylinder length="0.6" radius="0.1"/>
      </geometry>
      <origin rpy="0 1.57285 0" xyz="0.3 0 0"/>
      <material name="red">
        <color rgba="1 0 0 1"/>
      </material>
    </collision>
  </link>
  <link name="env+c+'_4'">
    <visual>
      <geometry>
        <sphere radius="0.1"/>
      </geometry>
      <origin rpy="0 1.57285 0" xyz="0.3 0 0"/>
      <material name="red">
        <color rgba="1 0 0 1"/>
      </material>
    </visual>
    <collision>
      <geometry>
        <sphere radius="0.1"/>
      </geometry>
      <origin rpy="0 1.57285 0" xyz="0.3 0 0"/>
      <material name="red">
        <color rgba="1 0 0 1"/>
      </material>
    </collision>
  </link>
  <joint name="env+c+'_1_2'" type="revolute">
    <parent link="env+c+'_1'"/>
    <child link="env+c+'_2'"/>
    <origin rpy="0 0 0" xyz="0.4 0 0"/>
    <axis xyz="0 1 0"/>
    <limit effort="300" lower="-1.57" upper="1.57" velocity="0.1"/>
  </joint>
  <joint name="env+c+'_2_3'" type="revolute">
    <parent link="env+c+'_2'"/>
    <child link="env+c+'_3'"/>
    <origin rpy="0 0 0" xyz="0.5 0 0"/>
    <axis xyz="0 1 0"/>
    <limit effort="300" lower="-1.57" upper="1.57" velocity="0.1"/>
  </joint>
  <joint name="env+c+'_3_4'" type="fixed">
    <parent link="env+c+'_3'"/>
    <child link="env+c+'_4'"/>
    <origin xyz="0.3 0 0"/>
  </joint>
  <link name="env+d+'_1'">
    <visual>
      <geometry>
        <cylinder length="0.4" radius="0.1"/>
      </geometry>
      <origin rpy="0 1.57285 0" xyz="0.2 0 0"/>
      <material name="cyan">
        <color rgba="0 1 1 1"/>
      </material>
    </visual>
  </link>
  <link name="env+d+'_2'">
    <visual>
      <geometry>
        <cylinder length="0.5" radius="0.1"/>
      </geometry>
      <origin rpy="0 1.57285 0" xyz="0.25 0 0"/>
      <material name="yellow">
        <color rgba="1 1 0 1"/>
      </material>
    </visual>
    <collision>
      <geometry>
        <cylinder length="0.5" radius="0.1"/>
      </geometry>
      <origin rpy="0 1.57285 0" xyz="0.25 0 0"/>
      <material name="yellow">
        <color rgba="1 1 0 1"/>
      </material>
    </collision>
  </link>
  <link name="env+d+'_3'">
    <visual>
      <geometry>
        <cylinder length="0.6" radius="0.1"/>
      </geometry>
      <origin rpy="0 1.57285 0" xyz="0.3 0 0"/>
      <material name="red">
        <color rgba="1 0 0 1"/>
      </material>
    </visual>
    <collision>
      <geometry>
        <cylinder length="0.6" radius="0.1"/>
      </geometry>
      <origin rpy="0 1.57285 0" xyz="0.3 0 0"/>
      <material name="red">
        <color rgba="1 0 0 1"/>
      </material>
    </collision>
  </link>
  <link name="env+d+'_4'">
    <visual>
      <geometry>
        <sphere radius="0.1"/>
      </geometry>
      <origin rpy="0 1.57285 0" xyz="0.3 0 0"/>
      <material name="red">
        <color rgba="1 0 0 1"/>
      </material>
    </visual>
    <collision>
      <geometry>
        <sphere radius="0.1"/>
      </geometry>
      <origin rpy="0 1.57285 0" xyz="0.3 0 0"/>
      <material name="red">
        <color rgba="1 0 0 1"/>
      </material>
    </collision>
  </link>
  <joint name="env+d+'_1_2'" type="revolute">
    <parent link="env+d+'_1'"/>
    <child link="env+d+'_2'"/>
    <origin rpy="0 0 0" xyz="0.4 0 0"/>
    <axis xyz="0 1 0"/>
    <limit effort="300" lower="-1.57" upper="1.57" velocity="0.1"/>
  </joint>
  <joint name="env+d+'_2_3'" type="revolute">
    <parent link="env+d+'_2'"/>
    <child link="env+d+'_3'"/>
    <origin rpy="0 0 0" xyz="0.5 0 0"/>
    <axis xyz="0 1 0"/>
    <limit effort="300" lower="-1.57" upper="1.57" velocity="0.1"/>
  </joint>
  <joint name="env+d+'_3_4'" type="fixed">
    <parent link="env+d+'_3'"/>
    <child link="env+d+'_4'"/>
    <origin xyz="0.3 0 0"/>
  </joint>
  <link name="env+base_link">
    <visual>
      <geometry>
        <box size="1 1 0.25"/>
      </geometry>
      <origin rpy="0 0 0" xyz="0 0 0"/>
      <material name="cyan">
        <color rgba="0 1 1 1"/>
      </material>
    </visual>
  </link>
  <link name="env+base_link2">
    <visual>
      <geometry>
        <box size="1 1 0.1"/>
      </geometry>
      <origin rpy="0 0 0" xyz="0 0 0"/>
      <material name="cyan">
        <color rgba="1 0 0 1"/>
      </material>
    </visual>
    <collision>
      <geometry>
        <box size="1 1 0.1"/>
      </geometry>
      <origin rpy="0 0 0" xyz="0 0 0"/>
      <material name="cyan">
        <color rgba="1 0 0 1"/>
      </material>
    </collision>
  </link>
  <joint name="env+base" type="fixed">
    <parent link="env+base_link"/>
    <child link="env+base_link2"/>
    <origin xyz="0 0 -0.075"/>
  </joint>
  <joint name="env+joint_0_a" type="revolute">
    <parent link="env+base_link"/>
    <child link="env+a+'_1'"/>
    <origin rpy="0 0 0.786425" xyz="0.5 0.5 0"/>
    <axis xyz="0 0 1"/>
    <limit effort="300" lower="-1.57" upper="1.57" velocity="0.1"/>
  </joint>
  <joint name="env+joint_0_b" type="revolute">
    <parent link="env+base_link"/>
    <child link="env+b+'_1'"/>
    <origin rpy="0 0 2.359275" xyz="-0.5 0.5 0"/>
    <axis xyz="0 0 1"/>
    <limit effort="300" lower="-1.57" upper="1.57" velocity="0.1"/>
  </joint>
  <joint name="env+joint_0_c" type="revolute">
    <parent link="env+base_link"/>
    <child link="env+c+'_1'"/>
    <origin rpy="0 0 3.932125" xyz="-0.5 -0.5 0"/>
    <axis xyz="0 0 1"/>
    <limit effort="300" lower="-1.57" upper="1.57" velocity="0.1"/>
  </joint>
  <joint name="env+joint_0_d" type="revolute">
    <parent link="env+base_link"/>
    <child link="env+d+'_1'"/>
    <origin rpy="0 0 5.504975" xyz="0.5 -0.5 0"/>
    <axis xyz="0 0 1"/>
    <limit effort="300" lower="-1.57" upper="1.57" velocity="0.1"/>
  </joint>
  <link name="sim+a+'_1'">
    <visual>
      <geometry>
        <cylinder length="0.4" radius="0.1"/>
      </geometry>
      <origin rpy="0 1.57285 0" xyz="0.2 0 0"/>
      <material name="cyan">
        <color rgba="0 1 1 1"/>
      </material>
    </visual>
  </link>
  <link name="sim+a+'_2'">
    <visual>
      <geometry>
        <cylinder length="0.5" radius="0.1"/>
      </geometry>
      <origin rpy="0 1.57285 0" xyz="0.25 0 0"/>
      <material name="yellow">
        <color rgba="1 1 0 1"/>
      </material>
    </visual>
    <collision>
      <geometry>
        <cylinder length="0.5" radius="0.1"/>
      </geometry>
      <origin rpy="0 1.57285 0" xyz="0.25 0 0"/>
      <material name="yellow">
        <color rgba="1 1 0 1"/>
      </material>
    </collision>
  </link>
  <link name="sim+a+'_3'">
    <visual>
      <geometry>
        <cylinder length="0.6" radius="0.1"/>
      </geometry>
      <origin rpy="0 1.57285 0" xyz="0.3 0 0"/>
      <material name="red">
        <color rgba="1 0 0 1"/>
      </material>
    </visual>
    <collision>
      <geometry>
        <cylinder length="0.6" radius="0.1"/>
      </geometry>
      <origin rpy="0 1.57285 0" xyz="0.3 0 0"/>
      <material name="red">
        <color rgba="1 0 0 1"/>
      </material>
    </collision>
  </link>
  <link name="sim+a+'_4'">
    <visual>
      <geometry>
        <sphere radius="0.1"/>
      </geometry>
      <origin rpy="0 1.57285 0" xyz="0.3 0 0"/>
      <material name="red">
        <color rgba="1 0 0 1"/>
      </material>
    </visual>
    <collision>
      <geometry>
        <sphere radius="0.1"/>
      </geometry>
      <origin rpy="0 1.57285 0" xyz="0.3 0 0"/>
      <material name="red">
        <color rgba="1 0 0 1"/>
      </material>
    </collision>
  </link>
  <joint name="sim+a+'_1_2'" type="revolute">
    <parent link="sim+a+'_1'"/>
    <child link="sim+a+'_2'"/>
    <origin rpy="0 0 0" xyz="0.4 0 0"/>
    <axis xyz="0 1 0"/>
    <limit effort="300" lower="-1.57" upper="1.57" velocity="0.1"/>
  </joint>
  <joint name="sim+a+'_2_3'" type="revolute">
    <parent link="sim+a+'_2'"/>
    <child link="sim+a+'_3'"/>
    <origin rpy="0 0 0" xyz="0.5 0 0"/>
    <axis xyz="0 1 0"/>
    <limit effort="300" lower="-1.57" upper="1.57" velocity="0.1"/>
  </joint>
  <joint name="sim+a+'_3_4'" type="fixed">
    <parent link="sim+a+'_3'"/>
    <child link="sim+a+'_4'"/>
    <origin xyz="0.3 0 0"/>
  </joint>
  <link name="sim+b+'_1'">
    <visual>
      <geometry>
        <cylinder length="0.4" radius="0.1"/>
      </geometry>
      <origin rpy="0 1.57285 0" xyz="0.2 0 0"/>
      <material name="cyan">
        <color rgba="0 1 1 1"/>
      </material>
    </visual>
  </link>
  <link name="sim+b+'_2'">
    <visual>
      <geometry>
        <cylinder length="0.5" radius="0.1"/>
      </geometry>
      <origin rpy="0 1.57285 0" xyz="0.25 0 0"/>
      <material name="yellow">
        <color rgba="1 1 0 1"/>
      </material>
    </visual>
    <collision>
      <geometry>
        <cylinder length="0.5" radius="0.1"/>
      </geometry>
      <origin rpy="0 1.57285 0" xyz="0.25 0 0"/>
      <material name="yellow">
        <color rgba="1 1 0 1"/>
      </material>
    </collision>
  </link>
  <link name="sim+b+'_3'">
    <visual>
      <geometry>
        <cylinder length="0.6" radius="0.1"/>
      </geometry>
      <origin rpy="0 1.57285 0" xyz="0.3 0 0"/>
      <material name="red">
        <color rgba="1 0 0 1"/>
      </material>
    </visual>
    <collision>
      <geometry>
        <cylinder length="0.6" radius="0.1"/>
      </geometry>
      <origin rpy="0 1.57285 0" xyz="0.3 0 0"/>
      <material name="red">
        <color rgba="1 0 0 1"/>
      </material>
    </collision>
  </link>
  <link name="sim+b+'_4'">
    <visual>
      <geometry>
        <sphere radius="0.1"/>
      </geometry>
      <origin rpy="0 1.57285 0" xyz="0.3 0 0"/>
      <material name="red">
        <color rgba="1 0 0 1"/>
      </material>
    </visual>
    <collision>
      <geometry>
        <sphere radius="0.1"/>
      </geometry>
      <origin rpy="0 1.57285 0" xyz="0.3 0 0"/>
      <material name="red">
        <color rgba="1 0 0 1"/>
      </material>
    </collision>
  </link>
  <joint name="sim+b+'_1_2'" type="revolute">
    <parent link="sim+b+'_1'"/>
    <child link="sim+b+'_2'"/>
    <origin rpy="0 0 0" xyz="0.4 0 0"/>
    <axis xyz="0 1 0"/>
    <limit effort="300" lower="-1.57" upper="1.57" velocity="0.1"/>
  </joint>
  <joint name="sim+b+'_2_3'" type="revolute">
    <parent link="sim+b+'_2'"/>
    <child link="sim+b+'_3'"/>
    <origin rpy="0 0 0" xyz="0.5 0 0"/>
    <axis xyz="0 1 0"/>
    <limit effort="300" lower="-1.57" upper="1.57" velocity="0.1"/>
  </joint>
  <joint name="sim+b+'_3_4'" type="fixed">
    <parent link="sim+b+'_3'"/>
    <child link="sim+b+'_4'"/>
    <origin xyz="0.3 0 0"/>
  </joint>
  <link name="sim+c+'_1'">
    <visual>
      <geometry>
        <cylinder length="0.4" radius="0.1"/>
      </geometry>
      <origin rpy="0 1.57285 0" xyz="0.2 0 0"/>
      <material name="cyan">
        <color rgba="0 1 1 1"/>
      </material>
    </visual>
  </link>
  <link name="sim+c+'_2'">
    <visual>
      <geometry>
        <cylinder length="0.5" radius="0.1"/>
      </geometry>
      <origin rpy="0 1.57285 0" xyz="0.25 0 0"/>
      <material name="yellow">
        <color rgba="1 1 0 1"/>
      </material>
    </visual>
    <collision>
      <geometry>
        <cylinder length="0.5" radius="0.1"/>
      </geometry>
      <origin rpy="0 1.57285 0" xyz="0.25 0 0"/>
      <material name="yellow">
        <color rgba="1 1 0 1"/>
      </material>
    </collision>
  </link>
  <link name="sim+c+'_3'">
    <visual>
      <geometry>
        <cylinder length="0.6" radius="0.1"/>
      </geometry>
      <origin rpy="0 1.57285 0" xyz="0.3 0 0"/>
      <material name="red">
        <color rgba="1 0 0 1"/>
      </material>
    </visual>
    <collision>
      <geometry>
        <cylinder length="0.6" radius="0.1"/>
      </geometry>
      <origin rpy="0 1.57285 0" xyz="0.3 0 0"/>
      <material name="red">
        <color rgba="1 0 0 1"/>
      </material>
    </collision>
  </link>
  <link name="sim+c+'_4'">
    <visual>
      <geometry>
        <sphere radius="0.1"/>
      </geometry>
      <origin rpy="0 1.57285 0" xyz="0.3 0 0"/>
      <material name="red">
        <color rgba="1 0 0 1"/>
      </material>
    </visual>
    <collision>
      <geometry>
        <sphere radius="0.1"/>
      </geometry>
      <origin rpy="0 1.57285 0" xyz="0.3 0 0"/>
      <material name="red">
        <color rgba="1 0 0 1"/>
      </material>
    </collision>
  </link>
  <joint name="sim+c+'_1_2'" type="revolute">
    <parent link="sim+c+'_1'"/>
    <child link="sim+c+'_2'"/>
    <origin rpy="0 0 0" xyz="0.4 0 0"/>
    <axis xyz="0 1 0"/>
    <limit effort="300" lower="-1.57" upper="1.57" velocity="0.1"/>
  </joint>
  <joint name="sim+c+'_2_3'" type="revolute">
    <parent link="sim+c+'_2'"/>
    <child link="sim+c+'_3'"/>
    <origin rpy="0 0 0" xyz="0.5 0 0"/>
    <axis xyz="0 1 0"/>
    <limit effort="300" lower="-1.57" upper="1.57" velocity="0.1"/>
  </joint>
  <joint name="sim+c+'_3_4'" type="fixed">
    <parent link="sim+c+'_3'"/>
    <child link="sim+c+'_4'"/>
    <origin xyz="0.3 0 0"/>
  </joint>
  <link name="sim+d+'_1'">
    <visual>
      <geometry>
        <cylinder length="0.4" radius="0.1"/>
      </geometry>
      <origin rpy="0 1.57285 0" xyz="0.2 0 0"/>
      <material name="cyan">
        <color rgba="0 1 1 1"/>
      </material>
    </visual>
  </link>
  <link name="sim+d+'_2'">
    <visual>
      <geometry>
        <cylinder length="0.5" radius="0.1"/>
      </geometry>
      <origin rpy="0 1.57285 0" xyz="0.25 0 0"/>
      <material name="yellow">
        <color rgba="1 1 0 1"/>
      </material>
    </visual>
    <collision>
      <geometry>
        <cylinder length="0.5" radius="0.1"/>
      </geometry>
      <origin rpy="0 1.57285 0" xyz="0.25 0 0"/>
      <material name="yellow">
        <color rgba="1 1 0 1"/>
      </material>
    </collision>
  </link>
  <link name="sim+d+'_3'">
    <visual>
      <geometry>
        <cylinder length="0.6" radius="0.1"/>
      </geometry>
      <origin rpy="0 1.57285 0" xyz="0.3 0 0"/>
      <material name="red">
        <color rgba="1 0 0 1"/>
      </material>
    </visual>
    <collision>
      <geometry>
        <cylinder length="0.6" radius="0.1"/>
      </geometry>
      <origin rpy="0 1.57285 0" xyz="0.3 0 0"/>
      <material name="red">
        <color rgba="1 0 0 1"/>
      </material>
    </collision>
  </link>
  <link name="sim+d+'_4'">
    <visual>
      <geometry>
        <sphere radius="0.1"/>
      </geometry>
      <origin rpy="0 1.57285 0" xyz="0.3 0 0"/>
      <material name="red">
        <color rgba="1 0 0 1"/>
      </material>
    </visual>
    <collision>
      <geometry>
        <sphere radius="0.1"/>
      </geometry>
      <origin rpy="0 1.57285 0" xyz="0.3 0 0"/>
      <material name="red">
        <color rgba="1 0 0 1"/>
      </material>
    </collision>
  </link>
  <joint name="sim+d+'_1_2'" type="revolute">
    <parent link="sim+d+'_1'"/>
    <child link="sim+d+'_2'"/>
    <origin rpy="0 0 0" xyz="0.4 0 0"/>
    <axis xyz="0 1 0"/>
    <limit effort="300" lower="-1.57" upper="1.57" velocity="0.1"/>
  </joint>
  <joint name="sim+d+'_2_3'" type="revolute">
    <parent link="sim+d+'_2'"/>
    <child link="sim+d+'_3'"/>
    <origin rpy="0 0 0" xyz="0.5 0 0"/>
    <axis xyz="0 1 0"/>
    <limit effort="300" lower="-1.57" upper="1.57" velocity="0.1"/>
  </joint>
  <joint name="sim+d+'_3_4'" type="fixed">
    <parent link="sim+d+'_3'"/>
    <child link="sim+d+'_4'"/>
    <origin xyz="0.3 0 0"/>
  </joint>
  <link name="sim+base_link">
    <visual>
      <geometry>
        <box size="1 1 0.25"/>
      </geometry>
      <origin rpy="0 0 0" xyz="0 0 0"/>
      <material name="cyan">
        <color rgba="0 1 1 1"/>
      </material>
    </visual>
  </link>
  <link name="sim+base_link2">
    <visual>
      <geometry>
        <box size="1 1 0.1"/>
      </geometry>
      <origin rpy="0 0 0" xyz="0 0 0"/>
      <material name="cyan">
        <color rgba="1 0 0 1"/>
      </material>
    </visual>
    <collision>
      <geometry>
        <box size="1 1 0.1"/>
      </geometry>
      <origin rpy="0 0 0" xyz="0 0 0"/>
      <material name="cyan">
        <color rgba="1 0 0 1"/>
      </material>
    </collision>
  </link>
  <joint name="sim+base" type="fixed">
    <parent link="sim+base_link"/>
    <child link="sim+base_link2"/>
    <origin xyz="0 0 -0.075"/>
  </joint>
  <joint name="sim+joint_0_a" type="revolute">
    <parent link="sim+base_link"/>
    <child link="sim+a+'_1'"/>
    <origin rpy="0 0 0.786425" xyz="0.5 0.5 0"/>
    <axis xyz="0 0 1"/>
    <limit effort="300" lower="-1.57" upper="1.57" velocity="0.1"/>
  </joint>
  <joint name="sim+joint_0_b" type="revolute">
    <parent link="sim+base_link"/>
    <child link="sim+b+'_1'"/>
    <origin rpy="0 0 2.359275" xyz="-0.5 0.5 0"/>
    <axis xyz="0 0 1"/>
    <limit effort="300" lower="-1.57" upper="1.57" velocity="0.1"/>
  </joint>
  <joint name="sim+joint_0_c" type="revolute">
    <parent link="sim+base_link"/>
    <child link="sim+c+'_1'"/>
    <origin rpy="0 0 3.932125" xyz="-0.5 -0.5 0"/>
    <axis xyz="0 0 1"/>
    <limit effort="300" lower="-1.57" upper="1.57" velocity="0.1"/>
  </joint>
  <joint name="sim+joint_0_d" type="revolute">
    <parent link="sim+base_link"/>
    <child link="sim+d+'_1'"/>
    <origin rpy="0 0 5.504975" xyz="0.5 -0.5 0"/>
    <axis xyz="0 0 1"/>
    <limit effort="300" lower="-1.57" upper="1.57" velocity="0.1"/>
  </joint>
  <joint name="base" type="fixed">
    <parent link="env+base_link"/>
    <child link="sim+base_link"/>
    <origin xyz="5 0 0"/>
  </joint>
</robot>
